2022-11-27 21:34:06,507 -  nornir.core -     INFO -        run() - Running task 'napalm_get' with args {'getters': ['facts', 'interfaces']} on 2 hosts
2022-11-27 21:36:27,254 -  nornir.core -     INFO -        run() - Running task 'napalm_get' with args {'getters': ['facts', 'interfaces_ip']} on 2 hosts
2022-11-27 21:41:28,458 -  nornir.core -     INFO -        run() - Running task 'netmiko_send_command' with args {'command_string': 'sh clock'} on 2 hosts
2022-11-27 21:41:52,245 -  nornir.core -     INFO -        run() - Running task 'netmiko_send_command' with args {'command_string': 'sh clock'} on 2 hosts
2022-11-27 21:54:49,444 -  nornir.core -     INFO -        run() - Running task 'netmiko_send_command' with args {'command_string': 'sh ip int brief'} on 2 hosts
2022-11-27 21:56:28,201 -  nornir.core -     INFO -        run() - Running task 'netmiko_send_command' with args {'command_string': 'sh ip int brief'} on 2 hosts
2022-11-27 21:56:28,207 - nornir.core.task -    ERROR -      start() - Host 'SW3': task 'netmiko_send_command' failed with traceback:
Traceback (most recent call last):
  File "/root/venv3/lib64/python3.9/site-packages/netmiko/base_connection.py", line 1046, in establish_connection
    self.remote_conn_pre.connect(**ssh_connect_params)
  File "/root/venv3/lib64/python3.9/site-packages/paramiko/client.py", line 381, in connect
    raise NoValidConnectionsError(errors)
paramiko.ssh_exception.NoValidConnectionsError: [Errno None] Unable to connect to port 22 on 10.0.2.23

During handling of the above exception, another exception occurred:

Traceback (most recent call last):
  File "/root/venv3/lib64/python3.9/site-packages/nornir/core/task.py", line 99, in start
    r = self.task(self, **self.params)
  File "/root/venv3/lib64/python3.9/site-packages/nornir_netmiko/tasks/netmiko_send_command.py", line 26, in netmiko_send_command
    net_connect = task.host.get_connection(CONNECTION_NAME, task.nornir.config)
  File "/root/venv3/lib64/python3.9/site-packages/nornir/core/inventory.py", line 494, in get_connection
    self.open_connection(
  File "/root/venv3/lib64/python3.9/site-packages/nornir/core/inventory.py", line 546, in open_connection
    conn_obj.open(
  File "/root/venv3/lib64/python3.9/site-packages/nornir_netmiko/connections/netmiko.py", line 59, in open
    connection = ConnectHandler(**parameters)
  File "/root/venv3/lib64/python3.9/site-packages/netmiko/ssh_dispatcher.py", line 365, in ConnectHandler
    return ConnectionClass(*args, **kwargs)
  File "/root/venv3/lib64/python3.9/site-packages/netmiko/base_connection.py", line 439, in __init__
    self._open()
  File "/root/venv3/lib64/python3.9/site-packages/netmiko/base_connection.py", line 444, in _open
    self.establish_connection()
  File "/root/venv3/lib64/python3.9/site-packages/netmiko/base_connection.py", line 1068, in establish_connection
    raise NetmikoTimeoutException(msg)
netmiko.exceptions.NetmikoTimeoutException: TCP connection to device failed.

Common causes of this problem are:
1. Incorrect hostname or IP address.
2. Wrong TCP port.
3. Intermediate firewall blocking access.

Device settings: cisco_ios 10.0.2.23:22



2022-11-27 21:56:28,208 - nornir.core.task -    ERROR -      start() - Host 'SW4': task 'netmiko_send_command' failed with traceback:
Traceback (most recent call last):
  File "/root/venv3/lib64/python3.9/site-packages/netmiko/base_connection.py", line 1046, in establish_connection
    self.remote_conn_pre.connect(**ssh_connect_params)
  File "/root/venv3/lib64/python3.9/site-packages/paramiko/client.py", line 381, in connect
    raise NoValidConnectionsError(errors)
paramiko.ssh_exception.NoValidConnectionsError: [Errno None] Unable to connect to port 22 on 10.0.2.24

During handling of the above exception, another exception occurred:

Traceback (most recent call last):
  File "/root/venv3/lib64/python3.9/site-packages/nornir/core/task.py", line 99, in start
    r = self.task(self, **self.params)
  File "/root/venv3/lib64/python3.9/site-packages/nornir_netmiko/tasks/netmiko_send_command.py", line 26, in netmiko_send_command
    net_connect = task.host.get_connection(CONNECTION_NAME, task.nornir.config)
  File "/root/venv3/lib64/python3.9/site-packages/nornir/core/inventory.py", line 494, in get_connection
    self.open_connection(
  File "/root/venv3/lib64/python3.9/site-packages/nornir/core/inventory.py", line 546, in open_connection
    conn_obj.open(
  File "/root/venv3/lib64/python3.9/site-packages/nornir_netmiko/connections/netmiko.py", line 59, in open
    connection = ConnectHandler(**parameters)
  File "/root/venv3/lib64/python3.9/site-packages/netmiko/ssh_dispatcher.py", line 365, in ConnectHandler
    return ConnectionClass(*args, **kwargs)
  File "/root/venv3/lib64/python3.9/site-packages/netmiko/base_connection.py", line 439, in __init__
    self._open()
  File "/root/venv3/lib64/python3.9/site-packages/netmiko/base_connection.py", line 444, in _open
    self.establish_connection()
  File "/root/venv3/lib64/python3.9/site-packages/netmiko/base_connection.py", line 1068, in establish_connection
    raise NetmikoTimeoutException(msg)
netmiko.exceptions.NetmikoTimeoutException: TCP connection to device failed.

Common causes of this problem are:
1. Incorrect hostname or IP address.
2. Wrong TCP port.
3. Intermediate firewall blocking access.

Device settings: cisco_ios 10.0.2.24:22



