    scrapli_conn = task.host.get_connection("scrapli", task.nornir.config)
  File "/root/venv3/lib64/python3.9/site-packages/nornir/core/inventory.py", line 494, in get_connection
    self.open_connection(
  File "/root/venv3/lib64/python3.9/site-packages/nornir/core/inventory.py", line 546, in open_connection
    conn_obj.open(
  File "/root/venv3/lib64/python3.9/site-packages/nornir_scrapli/connection.py", line 105, in open
    connection.open()
  File "/root/venv3/lib64/python3.9/site-packages/scrapli/driver/base/sync_driver.py", line 88, in open
    self.channel.channel_authenticate_ssh(
  File "/root/venv3/lib64/python3.9/site-packages/scrapli/decorators.py", line 216, in decorate
    return _multiprocessing_timeout(
  File "/root/venv3/lib64/python3.9/site-packages/scrapli/decorators.py", line 113, in _multiprocessing_timeout
    return future.result()
  File "/usr/lib64/python3.9/concurrent/futures/_base.py", line 439, in result
    return self.__get_result()
  File "/usr/lib64/python3.9/concurrent/futures/_base.py", line 391, in __get_result
    raise self._exception
  File "/usr/lib64/python3.9/concurrent/futures/thread.py", line 58, in run
    result = self.fn(*self.args, **self.kwargs)
  File "/root/venv3/lib64/python3.9/site-packages/scrapli/channel/sync_channel.py", line 287, in channel_authenticate_ssh
    buf = self.read()
  File "/root/venv3/lib64/python3.9/site-packages/scrapli/channel/sync_channel.py", line 69, in read
    buf = self.transport.read()
  File "/root/venv3/lib64/python3.9/site-packages/scrapli/decorators.py", line 216, in decorate
    return _multiprocessing_timeout(
  File "/root/venv3/lib64/python3.9/site-packages/scrapli/decorators.py", line 113, in _multiprocessing_timeout
    return future.result()
  File "/usr/lib64/python3.9/concurrent/futures/_base.py", line 439, in result
    return self.__get_result()
  File "/usr/lib64/python3.9/concurrent/futures/_base.py", line 391, in __get_result
    raise self._exception
  File "/usr/lib64/python3.9/concurrent/futures/thread.py", line 58, in run
    result = self.fn(*self.args, **self.kwargs)
  File "/root/venv3/lib64/python3.9/site-packages/scrapli/transport/plugins/system/transport.py", line 165, in read
    raise ScrapliConnectionError(msg) from exc
scrapli.exceptions.ScrapliConnectionError: encountered EOF reading from transport; typically means the device closed the connection

2022-12-02 19:07:58,958 - nornir.core.task -    ERROR -      start() - Host 'SW2': task 'get_prompt' failed with traceback:
Traceback (most recent call last):
  File "/root/venv3/lib64/python3.9/site-packages/scrapli/transport/plugins/system/ptyprocess.py", line 486, in read
    s = self.fileobj.read1(size)
OSError: [Errno 5] Input/output error

During handling of the above exception, another exception occurred:

Traceback (most recent call last):
  File "/root/venv3/lib64/python3.9/site-packages/scrapli/transport/plugins/system/transport.py", line 158, in read
    buf = self.session.read(65535)
  File "/root/venv3/lib64/python3.9/site-packages/scrapli/transport/plugins/system/ptyprocess.py", line 491, in read
    raise EOFError("End Of File (EOF). Exception style platform.")
EOFError: End Of File (EOF). Exception style platform.

The above exception was the direct cause of the following exception:

Traceback (most recent call last):
  File "/root/venv3/lib64/python3.9/site-packages/nornir/core/task.py", line 99, in start
    r = self.task(self, **self.params)
  File "/root/venv3/lib64/python3.9/site-packages/nornir_scrapli/tasks/core/get_prompt.py", line 19, in get_prompt
    scrapli_conn = task.host.get_connection("scrapli", task.nornir.config)
  File "/root/venv3/lib64/python3.9/site-packages/nornir/core/inventory.py", line 494, in get_connection
    self.open_connection(
  File "/root/venv3/lib64/python3.9/site-packages/nornir/core/inventory.py", line 546, in open_connection
    conn_obj.open(
  File "/root/venv3/lib64/python3.9/site-packages/nornir_scrapli/connection.py", line 105, in open
    connection.open()
  File "/root/venv3/lib64/python3.9/site-packages/scrapli/driver/base/sync_driver.py", line 88, in open
    self.channel.channel_authenticate_ssh(
  File "/root/venv3/lib64/python3.9/site-packages/scrapli/decorators.py", line 216, in decorate
    return _multiprocessing_timeout(
  File "/root/venv3/lib64/python3.9/site-packages/scrapli/decorators.py", line 113, in _multiprocessing_timeout
    return future.result()
  File "/usr/lib64/python3.9/concurrent/futures/_base.py", line 439, in result
    return self.__get_result()
  File "/usr/lib64/python3.9/concurrent/futures/_base.py", line 391, in __get_result
    raise self._exception
  File "/usr/lib64/python3.9/concurrent/futures/thread.py", line 58, in run
    result = self.fn(*self.args, **self.kwargs)
  File "/root/venv3/lib64/python3.9/site-packages/scrapli/channel/sync_channel.py", line 287, in channel_authenticate_ssh
    buf = self.read()
  File "/root/venv3/lib64/python3.9/site-packages/scrapli/channel/sync_channel.py", line 69, in read
    buf = self.transport.read()
  File "/root/venv3/lib64/python3.9/site-packages/scrapli/decorators.py", line 216, in decorate
    return _multiprocessing_timeout(
  File "/root/venv3/lib64/python3.9/site-packages/scrapli/decorators.py", line 113, in _multiprocessing_timeout
    return future.result()
  File "/usr/lib64/python3.9/concurrent/futures/_base.py", line 439, in result
    return self.__get_result()
  File "/usr/lib64/python3.9/concurrent/futures/_base.py", line 391, in __get_result
    raise self._exception
  File "/usr/lib64/python3.9/concurrent/futures/thread.py", line 58, in run
    result = self.fn(*self.args, **self.kwargs)
  File "/root/venv3/lib64/python3.9/site-packages/scrapli/transport/plugins/system/transport.py", line 165, in read
    raise ScrapliConnectionError(msg) from exc
scrapli.exceptions.ScrapliConnectionError: encountered EOF reading from transport; typically means the device closed the connection

2022-12-02 19:08:01,595 -  nornir.core -     INFO -        run() - Running task 'send_configs' with args {'configs': ['interface loop99', 'description Nornir loopback']} on 5 hosts
2022-12-02 19:08:01,966 -  nornir.core -     INFO -        run() - Running task 'send_command' with args {'command': 'wr mem'} on 5 hosts
2022-12-02 19:08:10,564 -  nornir.core -     INFO -        run() - Running task 'load_data' with args {} on 2 hosts
2022-12-02 19:45:02,893 -  nornir.core -     INFO -        run() - Running task 'netmiko_send_command' with args {'command_string': 'sh int switchport'} on 5 hosts
2022-12-02 19:45:03,034 - nornir.core.task -    ERROR -      start() - Host 'SW7': task 'netmiko_send_command' failed with traceback:
Traceback (most recent call last):
  File "/root/venv3/lib64/python3.9/site-packages/nornir/core/task.py", line 99, in start
    r = self.task(self, **self.params)
  File "/root/venv3/lib64/python3.9/site-packages/nornir_netmiko/tasks/netmiko_send_command.py", line 26, in netmiko_send_command
    net_connect = task.host.get_connection(CONNECTION_NAME, task.nornir.config)
  File "/root/venv3/lib64/python3.9/site-packages/nornir/core/inventory.py", line 494, in get_connection
    self.open_connection(
  File "/root/venv3/lib64/python3.9/site-packages/nornir/core/inventory.py", line 546, in open_connection
    conn_obj.open(
  File "/root/venv3/lib64/python3.9/site-packages/nornir_netmiko/connections/netmiko.py", line 59, in open
    connection = ConnectHandler(**parameters)
  File "/root/venv3/lib64/python3.9/site-packages/netmiko/ssh_dispatcher.py", line 354, in ConnectHandler
    device_type = kwargs["device_type"]
KeyError: 'device_type'

2022-12-02 19:52:14,235 -  nornir.core -     INFO -        run() - Running task 'netmiko_send_command' with args {'command_string': 'sh int switchport'} on 4 hosts
2022-12-02 19:54:52,912 -  nornir.core -     INFO -        run() - Running task 'netmiko_send_command' with args {'command_string': 'sh int switchport', 'use_textfsm': True} on 4 hosts
2022-12-02 20:00:57,192 -  nornir.core -     INFO -        run() - Running task 'netmiko_send_command' with args {'command_string': 'sh int switchport', 'use_textfsm': True} on 4 hosts
2022-12-02 20:11:49,381 -  nornir.core -     INFO -        run() - Running task 'netmiko_send_command' with args {'command_string': 'sh int switchport', 'use_textfsm': True} on 4 hosts
2022-12-02 20:25:10,306 -  nornir.core -     INFO -        run() - Running task 'host_parm' with args {} on 4 hosts
2022-12-02 20:40:21,990 -  nornir.core -     INFO -        run() - Running task 'netmiko_send_command' with args {'command_string': 'sh ip int bri', 'use_textfsm': True} on 4 hosts
2022-12-02 20:47:24,152 -  nornir.core -     INFO -        run() - Running task 'netmiko_send_command' with args {'command_string': 'sh ip int bri', 'use_textfsm': True} on 4 hosts
2022-12-02 20:47:57,398 -  nornir.core -     INFO -        run() - Running task 'netmiko_send_command' with args {'command_string': 'sh ip int bri', 'use_textfsm': True} on 4 hosts
2022-12-02 20:49:41,291 -  nornir.core -     INFO -        run() - Running task 'netmiko_send_command' with args {'command_string': 'sh ip int bri', 'use_textfsm': True} on 4 hosts
2022-12-02 20:52:42,978 -  nornir.core -     INFO -        run() - Running task 'netmiko_send_command' with args {'command_string': 'sh ip int bri', 'use_textfsm': True} on 4 hosts
2022-12-02 21:02:07,786 -  nornir.core -     INFO -        run() - Running task 'netmiko_send_command' with args {'command_string': 'sh ip int bri', 'use_textfsm': True} on 4 hosts
2022-12-02 21:04:13,560 -  nornir.core -     INFO -        run() - Running task 'netmiko_send_command' with args {'command_string': 'sh ip int bri', 'use_textfsm': True} on 4 hosts
2022-12-02 21:05:51,566 -  nornir.core -     INFO -        run() - Running task 'netmiko_send_command' with args {'command_string': 'sh ip int bri', 'use_textfsm': True} on 4 hosts
2022-12-02 21:07:23,086 -  nornir.core -     INFO -        run() - Running task 'netmiko_send_command' with args {'command_string': 'sh ip int bri', 'use_textfsm': True} on 4 hosts
2022-12-02 21:08:23,850 -  nornir.core -     INFO -        run() - Running task 'netmiko_send_command' with args {'command_string': 'sh ip int bri', 'use_textfsm': True} on 4 hosts
2022-12-02 21:11:22,217 -  nornir.core -     INFO -        run() - Running task 'netmiko_send_command' with args {'command_string': 'sh ip int bri', 'use_textfsm': True} on 4 hosts
2022-12-02 21:12:01,457 -  nornir.core -     INFO -        run() - Running task 'netmiko_send_command' with args {'command_string': 'sh ip int bri', 'use_textfsm': True} on 4 hosts
2022-12-03 08:41:14,926 -  nornir.core -     INFO -        run() - Running task 'netmiko_send_command' with args {'command_string': 'sh int switchport', 'use_textfsm': True} on 4 hosts
2022-12-03 08:49:01,263 -  nornir.core -     INFO -        run() - Running task 'netmiko_send_command' with args {'command_string': 'sh ip int bri', 'use_textfsm': True} on 4 hosts
2022-12-03 08:53:42,779 -  nornir.core -     INFO -        run() - Running task 'netmiko_send_command' with args {'command_string': 'sh ip int bri', 'use_textfsm': True} on 4 hosts
2022-12-03 09:06:58,600 -  nornir.core -     INFO -        run() - Running task 'netmiko_send_command' with args {'command_string': 'sh int', 'use_genie': True} on 4 hosts
2022-12-03 09:09:44,558 -  nornir.core -     INFO -        run() - Running task 'netmiko_send_command' with args {'command_string': 'sh int', 'use_genie': True} on 4 hosts
2022-12-03 09:10:34,119 -  nornir.core -     INFO -        run() - Running task 'netmiko_send_command' with args {'command_string': 'sh int', 'use_genie': True} on 4 hosts
2022-12-03 09:15:04,730 -  nornir.core -     INFO -        run() - Running task 'netmiko_send_command' with args {'command_string': 'sh ip int bri', 'use_genie': True} on 4 hosts
2022-12-03 09:18:13,549 -  nornir.core -     INFO -        run() - Running task 'netmiko_send_command' with args {'command_string': 'sh ip int bri', 'use_textfsm': True} on 4 hosts
2022-12-03 09:25:56,625 -  nornir.core -     INFO -        run() - Running task 'netmiko_send_command' with args {'command_string': 'sh ip int bri', 'use_textfsm': True} on 4 hosts
2022-12-03 09:27:50,402 -  nornir.core -     INFO -        run() - Running task 'netmiko_send_command' with args {'command_string': 'sh ip int bri', 'use_textfsm': True} on 4 hosts
2022-12-03 09:29:43,467 -  nornir.core -     INFO -        run() - Running task 'netmiko_send_command' with args {'command_string': 'sh ip int bri', 'use_textfsm': True} on 4 hosts
2022-12-03 09:30:47,920 -  nornir.core -     INFO -        run() - Running task 'netmiko_send_command' with args {'command_string': 'sh ip int bri', 'use_textfsm': True} on 4 hosts
2022-12-05 11:43:07,538 -  nornir.core -     INFO -        run() - Running task 'napalm_get' with args {'getters': ['facts', 'interfaces_ip']} on 6 hosts
2022-12-05 11:43:07,622 - nornir.core.task -    ERROR -      start() - Host 'CE1': task 'napalm_get' failed with traceback:
Traceback (most recent call last):
  File "/root/venv3/lib64/python3.9/site-packages/nornir/core/task.py", line 99, in start
    r = self.task(self, **self.params)
  File "/root/venv3/lib64/python3.9/site-packages/nornir_napalm/plugins/tasks/napalm_get.py", line 32, in napalm_get
    device = task.host.get_connection(CONNECTION_NAME, task.nornir.config)
  File "/root/venv3/lib64/python3.9/site-packages/nornir/core/inventory.py", line 494, in get_connection
    self.open_connection(
  File "/root/venv3/lib64/python3.9/site-packages/nornir/core/inventory.py", line 546, in open_connection
    conn_obj.open(
  File "/root/venv3/lib64/python3.9/site-packages/nornir_napalm/plugins/connections/__init__.py", line 55, in open
    network_driver = get_network_driver(platform)
  File "/root/venv3/lib64/python3.9/site-packages/napalm/base/__init__.py", line 99, in get_network_driver
    raise ModuleImportError(
napalm.base.exceptions.ModuleImportError: Cannot import "huawei_vrp". Is the library installed?

2022-12-05 11:43:07,624 - nornir.core.task -    ERROR -      start() - Host 'PE1': task 'napalm_get' failed with traceback:
Traceback (most recent call last):
  File "/root/venv3/lib64/python3.9/site-packages/nornir/core/task.py", line 99, in start
    r = self.task(self, **self.params)
  File "/root/venv3/lib64/python3.9/site-packages/nornir_napalm/plugins/tasks/napalm_get.py", line 32, in napalm_get
    device = task.host.get_connection(CONNECTION_NAME, task.nornir.config)
  File "/root/venv3/lib64/python3.9/site-packages/nornir/core/inventory.py", line 494, in get_connection
    self.open_connection(
  File "/root/venv3/lib64/python3.9/site-packages/nornir/core/inventory.py", line 546, in open_connection
    conn_obj.open(
  File "/root/venv3/lib64/python3.9/site-packages/nornir_napalm/plugins/connections/__init__.py", line 55, in open
    network_driver = get_network_driver(platform)
  File "/root/venv3/lib64/python3.9/site-packages/napalm/base/__init__.py", line 99, in get_network_driver
    raise ModuleImportError(
napalm.base.exceptions.ModuleImportError: Cannot import "huawei_vrp". Is the library installed?

2022-12-05 12:49:20,576 -  nornir.core -     INFO -        run() - Running task 'napalm_get' with args {'getters': ['facts', 'interfaces_ip']} on 6 hosts
2022-12-05 12:59:58,090 -  nornir.core -     INFO -        run() - Running task 'netmiko_send_command' with args {'command_string': 'disp ip int brief'} on 2 hosts
2022-12-05 12:59:58,100 - nornir.core.task -    ERROR -      start() - Host 'PE1': task 'netmiko_send_command' failed with traceback:
Traceback (most recent call last):
  File "/root/venv3/lib64/python3.9/site-packages/nornir/core/task.py", line 99, in start
    r = self.task(self, **self.params)
  File "/root/venv3/lib64/python3.9/site-packages/nornir_netmiko/tasks/netmiko_send_command.py", line 26, in netmiko_send_command
    net_connect = task.host.get_connection(CONNECTION_NAME, task.nornir.config)
  File "/root/venv3/lib64/python3.9/site-packages/nornir/core/inventory.py", line 494, in get_connection
    self.open_connection(
  File "/root/venv3/lib64/python3.9/site-packages/nornir/core/inventory.py", line 546, in open_connection
    conn_obj.open(
  File "/root/venv3/lib64/python3.9/site-packages/nornir_netmiko/connections/netmiko.py", line 59, in open
    connection = ConnectHandler(**parameters)
  File "/root/venv3/lib64/python3.9/site-packages/netmiko/ssh_dispatcher.py", line 360, in ConnectHandler
    raise ValueError(
ValueError: Unsupported 'device_type' currently supported platforms are: 
a10
accedian
adtran_os
alcatel_aos
alcatel_sros
allied_telesis_awplus
apresia_aeos
arista_eos
aruba_os
aruba_osswitch
aruba_procurve
audiocode_66
audiocode_72
audiocode_shell
avaya_ers
avaya_vsp
broadcom_icos
brocade_fastiron
brocade_fos
brocade_netiron
brocade_nos
brocade_vdx
brocade_vyos
calix_b6
cdot_cros
centec_os
checkpoint_gaia
ciena_saos
cisco_asa
cisco_ftd
cisco_ios
cisco_nxos
cisco_s300
cisco_tp
cisco_viptela
cisco_wlc
cisco_xe
cisco_xr
cloudgenix_ion
coriant
dell_dnos9
dell_force10
dell_isilon
dell_os10
dell_os6
dell_os9
dell_powerconnect
dell_sonic
dlink_ds
eltex
eltex_esr
endace
enterasys
ericsson_ipos
extreme
extreme_ers
extreme_exos
extreme_netiron
extreme_nos
extreme_slx
extreme_tierra
extreme_vdx
extreme_vsp
extreme_wing
f5_linux
f5_ltm
f5_tmsh
flexvnf
fortinet
generic
generic_termserver
hp_comware
hp_procurve
huawei
huawei_olt
huawei_smartax
huawei_vrpv8
ipinfusion_ocnos
juniper
juniper_junos
juniper_screenos
keymile
keymile_nos
linux
mellanox
mellanox_mlnxos
mikrotik_routeros
mikrotik_switchos
mrv_lx
mrv_optiswitch
netapp_cdot
netgear_prosafe
netscaler
nokia_srl
nokia_sros
oneaccess_oneos
ovs_linux
paloalto_panos
pluribus
quanta_mesh
rad_etx
raisecom_roap
ruckus_fastiron
ruijie_os
sixwind_os
sophos_sfos
supermicro_smis
tplink_jetstream
ubiquiti_edge
ubiquiti_edgerouter
ubiquiti_edgeswitch
ubiquiti_unifiswitch
vyatta_vyos
vyos
watchguard_fireware
yamaha
zte_zxros
zyxel_os

2022-12-05 12:59:58,101 - nornir.core.task -    ERROR -      start() - Host 'CE1': task 'netmiko_send_command' failed with traceback:
Traceback (most recent call last):
  File "/root/venv3/lib64/python3.9/site-packages/nornir/core/task.py", line 99, in start
    r = self.task(self, **self.params)
  File "/root/venv3/lib64/python3.9/site-packages/nornir_netmiko/tasks/netmiko_send_command.py", line 26, in netmiko_send_command
    net_connect = task.host.get_connection(CONNECTION_NAME, task.nornir.config)
  File "/root/venv3/lib64/python3.9/site-packages/nornir/core/inventory.py", line 494, in get_connection
    self.open_connection(
  File "/root/venv3/lib64/python3.9/site-packages/nornir/core/inventory.py", line 546, in open_connection
    conn_obj.open(
  File "/root/venv3/lib64/python3.9/site-packages/nornir_netmiko/connections/netmiko.py", line 59, in open
    connection = ConnectHandler(**parameters)
  File "/root/venv3/lib64/python3.9/site-packages/netmiko/ssh_dispatcher.py", line 360, in ConnectHandler
    raise ValueError(
ValueError: Unsupported 'device_type' currently supported platforms are: 
a10
accedian
adtran_os
alcatel_aos
alcatel_sros
allied_telesis_awplus
apresia_aeos
arista_eos
aruba_os
aruba_osswitch
aruba_procurve
audiocode_66
audiocode_72
audiocode_shell
avaya_ers
avaya_vsp
broadcom_icos
brocade_fastiron
brocade_fos
brocade_netiron
brocade_nos
brocade_vdx
brocade_vyos
calix_b6
cdot_cros
centec_os
checkpoint_gaia
ciena_saos
cisco_asa
cisco_ftd
cisco_ios
cisco_nxos
cisco_s300
cisco_tp
cisco_viptela
cisco_wlc
cisco_xe
cisco_xr
cloudgenix_ion
coriant
dell_dnos9
dell_force10
dell_isilon
dell_os10
dell_os6
dell_os9
dell_powerconnect
dell_sonic
dlink_ds
eltex
eltex_esr
endace
enterasys
ericsson_ipos
extreme
extreme_ers
extreme_exos
extreme_netiron
extreme_nos
extreme_slx
extreme_tierra
extreme_vdx
extreme_vsp
extreme_wing
f5_linux
f5_ltm
f5_tmsh
flexvnf
fortinet
generic
generic_termserver
hp_comware
hp_procurve
huawei
huawei_olt
huawei_smartax
huawei_vrpv8
ipinfusion_ocnos
juniper
juniper_junos
juniper_screenos
keymile
keymile_nos
linux
mellanox
mellanox_mlnxos
mikrotik_routeros
mikrotik_switchos
mrv_lx
mrv_optiswitch
netapp_cdot
netgear_prosafe
netscaler
nokia_srl
nokia_sros
oneaccess_oneos
ovs_linux
paloalto_panos
pluribus
quanta_mesh
rad_etx
raisecom_roap
ruckus_fastiron
ruijie_os
sixwind_os
sophos_sfos
supermicro_smis
tplink_jetstream
ubiquiti_edge
ubiquiti_edgerouter
ubiquiti_edgeswitch
ubiquiti_unifiswitch
vyatta_vyos
vyos
watchguard_fireware
yamaha
zte_zxros
zyxel_os

2022-12-05 13:03:39,993 -  nornir.core -     INFO -        run() - Running task 'netmiko_send_command' with args {'command_string': 'disp ip int brief'} on 2 hosts
2022-12-05 13:04:52,987 -  nornir.core -     INFO -        run() - Running task 'netmiko_send_command' with args {'command_string': 'disp ip int brief'} on 2 hosts
2022-12-05 13:06:54,051 -  nornir.core -     INFO -        run() - Running task "Backing up SW's configuration" with args {} on 2 hosts
2022-12-05 13:06:54,063 - nornir.core.task -    ERROR -      start() - Host 'CE1': task 'napalm_get' failed with traceback:
Traceback (most recent call last):
  File "/root/venv3/lib64/python3.9/site-packages/nornir/core/task.py", line 99, in start
    r = self.task(self, **self.params)
  File "/root/venv3/lib64/python3.9/site-packages/nornir_napalm/plugins/tasks/napalm_get.py", line 32, in napalm_get
    device = task.host.get_connection(CONNECTION_NAME, task.nornir.config)
  File "/root/venv3/lib64/python3.9/site-packages/nornir/core/inventory.py", line 494, in get_connection
    self.open_connection(
  File "/root/venv3/lib64/python3.9/site-packages/nornir/core/inventory.py", line 546, in open_connection
    conn_obj.open(
  File "/root/venv3/lib64/python3.9/site-packages/nornir_napalm/plugins/connections/__init__.py", line 55, in open
    network_driver = get_network_driver(platform)
  File "/root/venv3/lib64/python3.9/site-packages/napalm/base/__init__.py", line 99, in get_network_driver
    raise ModuleImportError(
napalm.base.exceptions.ModuleImportError: Cannot import "huawei_vrpv8". Is the library installed?

2022-12-05 13:06:54,065 - nornir.core.task -    ERROR -      start() - Host 'PE1': task 'napalm_get' failed with traceback:
Traceback (most recent call last):
  File "/root/venv3/lib64/python3.9/site-packages/nornir/core/task.py", line 99, in start
    r = self.task(self, **self.params)
  File "/root/venv3/lib64/python3.9/site-packages/nornir_napalm/plugins/tasks/napalm_get.py", line 32, in napalm_get
    device = task.host.get_connection(CONNECTION_NAME, task.nornir.config)
  File "/root/venv3/lib64/python3.9/site-packages/nornir/core/inventory.py", line 494, in get_connection
    self.open_connection(
  File "/root/venv3/lib64/python3.9/site-packages/nornir/core/inventory.py", line 546, in open_connection
    conn_obj.open(
  File "/root/venv3/lib64/python3.9/site-packages/nornir_napalm/plugins/connections/__init__.py", line 55, in open
    network_driver = get_network_driver(platform)
  File "/root/venv3/lib64/python3.9/site-packages/napalm/base/__init__.py", line 99, in get_network_driver
    raise ModuleImportError(
napalm.base.exceptions.ModuleImportError: Cannot import "huawei_vrpv8". Is the library installed?

2022-12-05 13:06:54,066 - nornir.core.task -    ERROR -      start() - Host 'CE1': task "Backing up SW's configuration" failed with traceback:
Traceback (most recent call last):
  File "/root/venv3/lib64/python3.9/site-packages/nornir/core/task.py", line 99, in start
    r = self.task(self, **self.params)
  File "/root/py/py_test/nornir7.py", line 12, in backup_configurations
    r=cisco.run(task=napalm_get, getters=["config"])
  File "/root/venv3/lib64/python3.9/site-packages/nornir/core/task.py", line 174, in run
    raise NornirSubTaskError(task=run_task, result=r)
nornir.core.exceptions.NornirSubTaskError: Subtask: napalm_get (failed)


2022-12-05 13:06:54,067 - nornir.core.task -    ERROR -      start() - Host 'PE1': task "Backing up SW's configuration" failed with traceback:
Traceback (most recent call last):
  File "/root/venv3/lib64/python3.9/site-packages/nornir/core/task.py", line 99, in start
    r = self.task(self, **self.params)
  File "/root/py/py_test/nornir7.py", line 12, in backup_configurations
    r=cisco.run(task=napalm_get, getters=["config"])
  File "/root/venv3/lib64/python3.9/site-packages/nornir/core/task.py", line 174, in run
    raise NornirSubTaskError(task=run_task, result=r)
nornir.core.exceptions.NornirSubTaskError: Subtask: napalm_get (failed)


2022-12-05 13:07:39,689 -  nornir.core -     INFO -        run() - Running task "Backing up SW's configuration" with args {} on 2 hosts
2022-12-05 13:10:16,597 -  nornir.core -     INFO -        run() - Running task 'netmiko_send_command' with args {'command_string': 'disp ip int brief'} on 2 hosts
2022-12-05 13:10:16,608 - nornir.core.task -    ERROR -      start() - Host 'PE1': task 'netmiko_send_command' failed with traceback:
Traceback (most recent call last):
  File "/root/venv3/lib64/python3.9/site-packages/nornir/core/task.py", line 99, in start
    r = self.task(self, **self.params)
  File "/root/venv3/lib64/python3.9/site-packages/nornir_netmiko/tasks/netmiko_send_command.py", line 26, in netmiko_send_command
    net_connect = task.host.get_connection(CONNECTION_NAME, task.nornir.config)
  File "/root/venv3/lib64/python3.9/site-packages/nornir/core/inventory.py", line 494, in get_connection
    self.open_connection(
  File "/root/venv3/lib64/python3.9/site-packages/nornir/core/inventory.py", line 546, in open_connection
    conn_obj.open(
  File "/root/venv3/lib64/python3.9/site-packages/nornir_netmiko/connections/netmiko.py", line 59, in open
    connection = ConnectHandler(**parameters)
  File "/root/venv3/lib64/python3.9/site-packages/netmiko/ssh_dispatcher.py", line 360, in ConnectHandler
    raise ValueError(
ValueError: Unsupported 'device_type' currently supported platforms are: 
a10
accedian
adtran_os
alcatel_aos
alcatel_sros
allied_telesis_awplus
apresia_aeos
arista_eos
aruba_os
aruba_osswitch
aruba_procurve
audiocode_66
audiocode_72
audiocode_shell
avaya_ers
avaya_vsp
broadcom_icos
brocade_fastiron
brocade_fos
brocade_netiron
brocade_nos
brocade_vdx
brocade_vyos
calix_b6
cdot_cros
centec_os
checkpoint_gaia
ciena_saos
cisco_asa
cisco_ftd
cisco_ios
cisco_nxos
cisco_s300
cisco_tp
cisco_viptela
cisco_wlc
cisco_xe
cisco_xr
cloudgenix_ion
coriant
dell_dnos9
dell_force10
dell_isilon
dell_os10
dell_os6
dell_os9
dell_powerconnect
dell_sonic
dlink_ds
eltex
eltex_esr
endace
enterasys
ericsson_ipos
extreme
extreme_ers
extreme_exos
extreme_netiron
extreme_nos
extreme_slx
extreme_tierra
extreme_vdx
extreme_vsp
extreme_wing
f5_linux
f5_ltm
f5_tmsh
flexvnf
fortinet
generic
generic_termserver
hp_comware
hp_procurve
huawei
huawei_olt
huawei_smartax
huawei_vrpv8
ipinfusion_ocnos
juniper
juniper_junos
juniper_screenos
keymile
keymile_nos
linux
mellanox
mellanox_mlnxos
mikrotik_routeros
mikrotik_switchos
mrv_lx
mrv_optiswitch
netapp_cdot
netgear_prosafe
netscaler
nokia_srl
nokia_sros
oneaccess_oneos
ovs_linux
paloalto_panos
pluribus
quanta_mesh
rad_etx
raisecom_roap
ruckus_fastiron
ruijie_os
sixwind_os
sophos_sfos
supermicro_smis
tplink_jetstream
ubiquiti_edge
ubiquiti_edgerouter
ubiquiti_edgeswitch
ubiquiti_unifiswitch
vyatta_vyos
vyos
watchguard_fireware
yamaha
zte_zxros
zyxel_os

2022-12-05 13:10:16,609 - nornir.core.task -    ERROR -      start() - Host 'CE1': task 'netmiko_send_command' failed with traceback:
Traceback (most recent call last):
  File "/root/venv3/lib64/python3.9/site-packages/nornir/core/task.py", line 99, in start
    r = self.task(self, **self.params)
  File "/root/venv3/lib64/python3.9/site-packages/nornir_netmiko/tasks/netmiko_send_command.py", line 26, in netmiko_send_command
    net_connect = task.host.get_connection(CONNECTION_NAME, task.nornir.config)
  File "/root/venv3/lib64/python3.9/site-packages/nornir/core/inventory.py", line 494, in get_connection
    self.open_connection(
  File "/root/venv3/lib64/python3.9/site-packages/nornir/core/inventory.py", line 546, in open_connection
    conn_obj.open(
  File "/root/venv3/lib64/python3.9/site-packages/nornir_netmiko/connections/netmiko.py", line 59, in open
    connection = ConnectHandler(**parameters)
  File "/root/venv3/lib64/python3.9/site-packages/netmiko/ssh_dispatcher.py", line 360, in ConnectHandler
    raise ValueError(
ValueError: Unsupported 'device_type' currently supported platforms are: 
a10
accedian
adtran_os
alcatel_aos
alcatel_sros
allied_telesis_awplus
apresia_aeos
arista_eos
aruba_os
aruba_osswitch
aruba_procurve
audiocode_66
audiocode_72
audiocode_shell
avaya_ers
avaya_vsp
broadcom_icos
brocade_fastiron
brocade_fos
brocade_netiron
brocade_nos
brocade_vdx
brocade_vyos
calix_b6
cdot_cros
centec_os
checkpoint_gaia
ciena_saos
cisco_asa
cisco_ftd
cisco_ios
cisco_nxos
cisco_s300
cisco_tp
cisco_viptela
cisco_wlc
cisco_xe
cisco_xr
cloudgenix_ion
coriant
dell_dnos9
dell_force10
dell_isilon
dell_os10
dell_os6
dell_os9
dell_powerconnect
dell_sonic
dlink_ds
eltex
eltex_esr
endace
enterasys
ericsson_ipos
extreme
extreme_ers
extreme_exos
extreme_netiron
extreme_nos
extreme_slx
extreme_tierra
extreme_vdx
extreme_vsp
extreme_wing
f5_linux
f5_ltm
f5_tmsh
flexvnf
fortinet
generic
generic_termserver
hp_comware
hp_procurve
huawei
huawei_olt
huawei_smartax
huawei_vrpv8
ipinfusion_ocnos
juniper
juniper_junos
juniper_screenos
keymile
keymile_nos
linux
mellanox
mellanox_mlnxos
mikrotik_routeros
mikrotik_switchos
mrv_lx
mrv_optiswitch
netapp_cdot
netgear_prosafe
netscaler
nokia_srl
nokia_sros
oneaccess_oneos
ovs_linux
paloalto_panos
pluribus
quanta_mesh
rad_etx
raisecom_roap
ruckus_fastiron
ruijie_os
sixwind_os
sophos_sfos
supermicro_smis
tplink_jetstream
ubiquiti_edge
ubiquiti_edgerouter
ubiquiti_edgeswitch
ubiquiti_unifiswitch
vyatta_vyos
vyos
watchguard_fireware
yamaha
zte_zxros
zyxel_os

2022-12-05 13:11:04,806 -  nornir.core -     INFO -        run() - Running task 'netmiko_send_command' with args {'command_string': 'disp ip int brief'} on 2 hosts
2022-12-05 13:11:19,999 -  nornir.core -     INFO -        run() - Running task "Backing up SW's configuration" with args {} on 2 hosts
2022-12-05 13:11:20,011 - nornir.core.task -    ERROR -      start() - Host 'CE1': task 'napalm_get' failed with traceback:
Traceback (most recent call last):
  File "/root/venv3/lib64/python3.9/site-packages/nornir/core/task.py", line 99, in start
    r = self.task(self, **self.params)
  File "/root/venv3/lib64/python3.9/site-packages/nornir_napalm/plugins/tasks/napalm_get.py", line 32, in napalm_get
    device = task.host.get_connection(CONNECTION_NAME, task.nornir.config)
  File "/root/venv3/lib64/python3.9/site-packages/nornir/core/inventory.py", line 494, in get_connection
    self.open_connection(
  File "/root/venv3/lib64/python3.9/site-packages/nornir/core/inventory.py", line 546, in open_connection
    conn_obj.open(
  File "/root/venv3/lib64/python3.9/site-packages/nornir_napalm/plugins/connections/__init__.py", line 55, in open
    network_driver = get_network_driver(platform)
  File "/root/venv3/lib64/python3.9/site-packages/napalm/base/__init__.py", line 99, in get_network_driver
    raise ModuleImportError(
napalm.base.exceptions.ModuleImportError: Cannot import "huawei". Is the library installed?

2022-12-05 13:11:20,012 - nornir.core.task -    ERROR -      start() - Host 'PE1': task 'napalm_get' failed with traceback:
Traceback (most recent call last):
  File "/root/venv3/lib64/python3.9/site-packages/nornir/core/task.py", line 99, in start
    r = self.task(self, **self.params)
  File "/root/venv3/lib64/python3.9/site-packages/nornir_napalm/plugins/tasks/napalm_get.py", line 32, in napalm_get
    device = task.host.get_connection(CONNECTION_NAME, task.nornir.config)
  File "/root/venv3/lib64/python3.9/site-packages/nornir/core/inventory.py", line 494, in get_connection
    self.open_connection(
  File "/root/venv3/lib64/python3.9/site-packages/nornir/core/inventory.py", line 546, in open_connection
    conn_obj.open(
  File "/root/venv3/lib64/python3.9/site-packages/nornir_napalm/plugins/connections/__init__.py", line 55, in open
    network_driver = get_network_driver(platform)
  File "/root/venv3/lib64/python3.9/site-packages/napalm/base/__init__.py", line 99, in get_network_driver
    raise ModuleImportError(
napalm.base.exceptions.ModuleImportError: Cannot import "huawei". Is the library installed?

2022-12-05 13:11:20,015 - nornir.core.task -    ERROR -      start() - Host 'CE1': task "Backing up SW's configuration" failed with traceback:
Traceback (most recent call last):
  File "/root/venv3/lib64/python3.9/site-packages/nornir/core/task.py", line 99, in start
    r = self.task(self, **self.params)
  File "/root/py/py_test/nornir7.py", line 12, in backup_configurations
    r=cisco.run(task=napalm_get, getters=["config"])
  File "/root/venv3/lib64/python3.9/site-packages/nornir/core/task.py", line 174, in run
    raise NornirSubTaskError(task=run_task, result=r)
nornir.core.exceptions.NornirSubTaskError: Subtask: napalm_get (failed)


2022-12-05 13:11:20,015 - nornir.core.task -    ERROR -      start() - Host 'PE1': task "Backing up SW's configuration" failed with traceback:
Traceback (most recent call last):
  File "/root/venv3/lib64/python3.9/site-packages/nornir/core/task.py", line 99, in start
    r = self.task(self, **self.params)
  File "/root/py/py_test/nornir7.py", line 12, in backup_configurations
    r=cisco.run(task=napalm_get, getters=["config"])
  File "/root/venv3/lib64/python3.9/site-packages/nornir/core/task.py", line 174, in run
    raise NornirSubTaskError(task=run_task, result=r)
nornir.core.exceptions.NornirSubTaskError: Subtask: napalm_get (failed)


2022-12-05 13:11:55,240 -  nornir.core -     INFO -        run() - Running task "Backing up SW's configuration" with args {} on 2 hosts
2022-12-05 13:24:09,078 -  nornir.core -     INFO -        run() - Running task "Backing up SW's configuration" with args {} on 2 hosts
2022-12-05 23:01:42,416 -  nornir.core -     INFO -        run() - Running task 'netmiko_send_command' with args {'command_string': 'disp ip int bri', 'use_textfsm': True} on 6 hosts
2022-12-05 23:01:42,442 - nornir.core.task -    ERROR -      start() - Host 'CE1': task 'netmiko_send_command' failed with traceback:
Traceback (most recent call last):
  File "/root/venv3/lib64/python3.9/site-packages/nornir/core/task.py", line 99, in start
    r = self.task(self, **self.params)
  File "/root/venv3/lib64/python3.9/site-packages/nornir_netmiko/tasks/netmiko_send_command.py", line 26, in netmiko_send_command
    net_connect = task.host.get_connection(CONNECTION_NAME, task.nornir.config)
  File "/root/venv3/lib64/python3.9/site-packages/nornir/core/inventory.py", line 494, in get_connection
    self.open_connection(
  File "/root/venv3/lib64/python3.9/site-packages/nornir/core/inventory.py", line 546, in open_connection
    conn_obj.open(
  File "/root/venv3/lib64/python3.9/site-packages/nornir_netmiko/connections/netmiko.py", line 59, in open
    connection = ConnectHandler(**parameters)
  File "/root/venv3/lib64/python3.9/site-packages/netmiko/ssh_dispatcher.py", line 360, in ConnectHandler
    raise ValueError(
ValueError: Unsupported 'device_type' currently supported platforms are: 
a10
accedian
adtran_os
alcatel_aos
alcatel_sros
allied_telesis_awplus
apresia_aeos
arista_eos
aruba_os
aruba_osswitch
aruba_procurve
audiocode_66
audiocode_72
audiocode_shell
avaya_ers
avaya_vsp
broadcom_icos
brocade_fastiron
brocade_fos
brocade_netiron
brocade_nos
brocade_vdx
brocade_vyos
calix_b6
cdot_cros
centec_os
checkpoint_gaia
ciena_saos
cisco_asa
cisco_ftd
cisco_ios
cisco_nxos
cisco_s300
cisco_tp
cisco_viptela
cisco_wlc
cisco_xe
cisco_xr
cloudgenix_ion
coriant
dell_dnos9
dell_force10
dell_isilon
dell_os10
dell_os6
dell_os9
dell_powerconnect
dell_sonic
dlink_ds
eltex
eltex_esr
endace
enterasys
ericsson_ipos
extreme
extreme_ers
extreme_exos
extreme_netiron
extreme_nos
extreme_slx
extreme_tierra
extreme_vdx
extreme_vsp
extreme_wing
f5_linux
f5_ltm
f5_tmsh
flexvnf
fortinet
generic
generic_termserver
hp_comware
hp_procurve
huawei
huawei_olt
huawei_smartax
huawei_vrpv8
ipinfusion_ocnos
juniper
juniper_junos
juniper_screenos
keymile
keymile_nos
linux
mellanox
mellanox_mlnxos
mikrotik_routeros
mikrotik_switchos
mrv_lx
mrv_optiswitch
netapp_cdot
netgear_prosafe
netscaler
nokia_srl
nokia_sros
oneaccess_oneos
ovs_linux
paloalto_panos
pluribus
quanta_mesh
rad_etx
raisecom_roap
ruckus_fastiron
ruijie_os
sixwind_os
sophos_sfos
supermicro_smis
tplink_jetstream
ubiquiti_edge
ubiquiti_edgerouter
ubiquiti_edgeswitch
ubiquiti_unifiswitch
vyatta_vyos
vyos
watchguard_fireware
yamaha
zte_zxros
zyxel_os

2022-12-05 23:01:42,443 - nornir.core.task -    ERROR -      start() - Host 'PE1': task 'netmiko_send_command' failed with traceback:
Traceback (most recent call last):
  File "/root/venv3/lib64/python3.9/site-packages/nornir/core/task.py", line 99, in start
    r = self.task(self, **self.params)
  File "/root/venv3/lib64/python3.9/site-packages/nornir_netmiko/tasks/netmiko_send_command.py", line 26, in netmiko_send_command
    net_connect = task.host.get_connection(CONNECTION_NAME, task.nornir.config)
  File "/root/venv3/lib64/python3.9/site-packages/nornir/core/inventory.py", line 494, in get_connection
    self.open_connection(
  File "/root/venv3/lib64/python3.9/site-packages/nornir/core/inventory.py", line 546, in open_connection
    conn_obj.open(
  File "/root/venv3/lib64/python3.9/site-packages/nornir_netmiko/connections/netmiko.py", line 59, in open
    connection = ConnectHandler(**parameters)
  File "/root/venv3/lib64/python3.9/site-packages/netmiko/ssh_dispatcher.py", line 360, in ConnectHandler
    raise ValueError(
ValueError: Unsupported 'device_type' currently supported platforms are: 
a10
accedian
adtran_os
alcatel_aos
alcatel_sros
allied_telesis_awplus
apresia_aeos
arista_eos
aruba_os
aruba_osswitch
aruba_procurve
audiocode_66
audiocode_72
audiocode_shell
avaya_ers
avaya_vsp
broadcom_icos
brocade_fastiron
brocade_fos
brocade_netiron
brocade_nos
brocade_vdx
brocade_vyos
calix_b6
cdot_cros
centec_os
checkpoint_gaia
ciena_saos
cisco_asa
cisco_ftd
cisco_ios
cisco_nxos
cisco_s300
cisco_tp
cisco_viptela
cisco_wlc
cisco_xe
cisco_xr
cloudgenix_ion
coriant
dell_dnos9
dell_force10
dell_isilon
dell_os10
dell_os6
dell_os9
dell_powerconnect
dell_sonic
dlink_ds
eltex
eltex_esr
endace
enterasys
ericsson_ipos
extreme
extreme_ers
extreme_exos
extreme_netiron
extreme_nos
extreme_slx
extreme_tierra
extreme_vdx
extreme_vsp
extreme_wing
f5_linux
f5_ltm
f5_tmsh
flexvnf
fortinet
generic
generic_termserver
hp_comware
hp_procurve
huawei
huawei_olt
huawei_smartax
huawei_vrpv8
ipinfusion_ocnos
juniper
juniper_junos
juniper_screenos
keymile
keymile_nos
linux
mellanox
mellanox_mlnxos
mikrotik_routeros
mikrotik_switchos
mrv_lx
mrv_optiswitch
netapp_cdot
netgear_prosafe
netscaler
nokia_srl
nokia_sros
oneaccess_oneos
ovs_linux
paloalto_panos
pluribus
quanta_mesh
rad_etx
raisecom_roap
ruckus_fastiron
ruijie_os
sixwind_os
sophos_sfos
supermicro_smis
tplink_jetstream
ubiquiti_edge
ubiquiti_edgerouter
ubiquiti_edgeswitch
ubiquiti_unifiswitch
vyatta_vyos
vyos
watchguard_fireware
yamaha
zte_zxros
zyxel_os

2022-12-05 23:04:47,334 -  nornir.core -     INFO -        run() - Running task 'netmiko_send_command' with args {'command_string': 'sh ip int bri', 'use_textfsm': True} on 2 hosts
2022-12-05 23:05:15,702 -  nornir.core -     INFO -        run() - Running task 'netmiko_send_command' with args {'command_string': 'disp ip int bri', 'use_textfsm': True} on 2 hosts
2022-12-05 23:05:15,711 - nornir.core.task -    ERROR -      start() - Host 'PE1': task 'netmiko_send_command' failed with traceback:
Traceback (most recent call last):
  File "/root/venv3/lib64/python3.9/site-packages/nornir/core/task.py", line 99, in start
    r = self.task(self, **self.params)
  File "/root/venv3/lib64/python3.9/site-packages/nornir_netmiko/tasks/netmiko_send_command.py", line 26, in netmiko_send_command
    net_connect = task.host.get_connection(CONNECTION_NAME, task.nornir.config)
  File "/root/venv3/lib64/python3.9/site-packages/nornir/core/inventory.py", line 494, in get_connection
    self.open_connection(
  File "/root/venv3/lib64/python3.9/site-packages/nornir/core/inventory.py", line 546, in open_connection
    conn_obj.open(
  File "/root/venv3/lib64/python3.9/site-packages/nornir_netmiko/connections/netmiko.py", line 59, in open
    connection = ConnectHandler(**parameters)
  File "/root/venv3/lib64/python3.9/site-packages/netmiko/ssh_dispatcher.py", line 360, in ConnectHandler
    raise ValueError(
ValueError: Unsupported 'device_type' currently supported platforms are: 
a10
accedian
adtran_os
alcatel_aos
alcatel_sros
allied_telesis_awplus
apresia_aeos
arista_eos
aruba_os
aruba_osswitch
aruba_procurve
audiocode_66
audiocode_72
audiocode_shell
avaya_ers
avaya_vsp
broadcom_icos
brocade_fastiron
brocade_fos
brocade_netiron
brocade_nos
brocade_vdx
brocade_vyos
calix_b6
cdot_cros
centec_os
checkpoint_gaia
ciena_saos
cisco_asa
cisco_ftd
cisco_ios
cisco_nxos
cisco_s300
cisco_tp
cisco_viptela
cisco_wlc
cisco_xe
cisco_xr
cloudgenix_ion
coriant
dell_dnos9
dell_force10
dell_isilon
dell_os10
dell_os6
dell_os9
dell_powerconnect
dell_sonic
dlink_ds
eltex
eltex_esr
endace
enterasys
ericsson_ipos
extreme
extreme_ers
extreme_exos
extreme_netiron
extreme_nos
extreme_slx
extreme_tierra
extreme_vdx
extreme_vsp
extreme_wing
f5_linux
f5_ltm
f5_tmsh
flexvnf
fortinet
generic
generic_termserver
hp_comware
hp_procurve
huawei
huawei_olt
huawei_smartax
huawei_vrpv8
ipinfusion_ocnos
juniper
juniper_junos
juniper_screenos
keymile
keymile_nos
linux
mellanox
mellanox_mlnxos
mikrotik_routeros
mikrotik_switchos
mrv_lx
mrv_optiswitch
netapp_cdot
netgear_prosafe
netscaler
nokia_srl
nokia_sros
oneaccess_oneos
ovs_linux
paloalto_panos
pluribus
quanta_mesh
rad_etx
raisecom_roap
ruckus_fastiron
ruijie_os
sixwind_os
sophos_sfos
supermicro_smis
tplink_jetstream
ubiquiti_edge
ubiquiti_edgerouter
ubiquiti_edgeswitch
ubiquiti_unifiswitch
vyatta_vyos
vyos
watchguard_fireware
yamaha
zte_zxros
zyxel_os

2022-12-05 23:05:15,712 - nornir.core.task -    ERROR -      start() - Host 'CE1': task 'netmiko_send_command' failed with traceback:
Traceback (most recent call last):
  File "/root/venv3/lib64/python3.9/site-packages/nornir/core/task.py", line 99, in start
    r = self.task(self, **self.params)
  File "/root/venv3/lib64/python3.9/site-packages/nornir_netmiko/tasks/netmiko_send_command.py", line 26, in netmiko_send_command
    net_connect = task.host.get_connection(CONNECTION_NAME, task.nornir.config)
  File "/root/venv3/lib64/python3.9/site-packages/nornir/core/inventory.py", line 494, in get_connection
    self.open_connection(
  File "/root/venv3/lib64/python3.9/site-packages/nornir/core/inventory.py", line 546, in open_connection
    conn_obj.open(
  File "/root/venv3/lib64/python3.9/site-packages/nornir_netmiko/connections/netmiko.py", line 59, in open
    connection = ConnectHandler(**parameters)
  File "/root/venv3/lib64/python3.9/site-packages/netmiko/ssh_dispatcher.py", line 360, in ConnectHandler
    raise ValueError(
ValueError: Unsupported 'device_type' currently supported platforms are: 
a10
accedian
adtran_os
alcatel_aos
alcatel_sros
allied_telesis_awplus
apresia_aeos
arista_eos
aruba_os
aruba_osswitch
aruba_procurve
audiocode_66
audiocode_72
audiocode_shell
avaya_ers
avaya_vsp
broadcom_icos
brocade_fastiron
brocade_fos
brocade_netiron
brocade_nos
brocade_vdx
brocade_vyos
calix_b6
cdot_cros
centec_os
checkpoint_gaia
ciena_saos
cisco_asa
cisco_ftd
cisco_ios
cisco_nxos
cisco_s300
cisco_tp
cisco_viptela
cisco_wlc
cisco_xe
cisco_xr
cloudgenix_ion
coriant
dell_dnos9
dell_force10
dell_isilon
dell_os10
dell_os6
dell_os9
dell_powerconnect
dell_sonic
dlink_ds
eltex
eltex_esr
endace
enterasys
ericsson_ipos
extreme
extreme_ers
extreme_exos
extreme_netiron
extreme_nos
extreme_slx
extreme_tierra
extreme_vdx
extreme_vsp
extreme_wing
f5_linux
f5_ltm
f5_tmsh
flexvnf
fortinet
generic
generic_termserver
hp_comware
hp_procurve
huawei
huawei_olt
huawei_smartax
huawei_vrpv8
ipinfusion_ocnos
juniper
juniper_junos
juniper_screenos
keymile
keymile_nos
linux
mellanox
mellanox_mlnxos
mikrotik_routeros
mikrotik_switchos
mrv_lx
mrv_optiswitch
netapp_cdot
netgear_prosafe
netscaler
nokia_srl
nokia_sros
oneaccess_oneos
ovs_linux
paloalto_panos
pluribus
quanta_mesh
rad_etx
raisecom_roap
ruckus_fastiron
ruijie_os
sixwind_os
sophos_sfos
supermicro_smis
tplink_jetstream
ubiquiti_edge
ubiquiti_edgerouter
ubiquiti_edgeswitch
ubiquiti_unifiswitch
vyatta_vyos
vyos
watchguard_fireware
yamaha
zte_zxros
zyxel_os

2022-12-05 23:08:58,625 -  nornir.core -     INFO -        run() - Running task 'netmiko_send_command' with args {'command_string': 'disp ip int bri', 'use_textfsm': True} on 2 hosts
2022-12-05 23:09:49,151 -  nornir.core -     INFO -        run() - Running task 'netmiko_send_command' with args {'command_string': 'sh ip int bri', 'use_textfsm': True} on 2 hosts
2022-12-05 23:11:33,705 -  nornir.core -     INFO -        run() - Running task 'netmiko_send_command' with args {'command_string': 'sh ip int bri', 'use_genie': True} on 2 hosts
2022-12-05 23:14:10,899 -  nornir.core -     INFO -        run() - Running task 'netmiko_send_command' with args {'command_string': 'disp ip int bri', 'use_genie': True} on 2 hosts
2022-12-05 23:14:22,608 - nornir.core.task -    ERROR -      start() - Host 'PE1': task 'netmiko_send_command' failed with traceback:
Traceback (most recent call last):
  File "/root/venv3/lib64/python3.9/site-packages/nornir/core/task.py", line 99, in start
    r = self.task(self, **self.params)
  File "/root/venv3/lib64/python3.9/site-packages/nornir_netmiko/tasks/netmiko_send_command.py", line 32, in netmiko_send_command
    result = net_connect.send_command(command_string, **kwargs)
  File "/root/venv3/lib64/python3.9/site-packages/netmiko/utilities.py", line 592, in wrapper_decorator
    return func(self, *args, **kwargs)
  File "/root/venv3/lib64/python3.9/site-packages/netmiko/base_connection.py", line 1721, in send_command
    raise ReadTimeout(msg)
netmiko.exceptions.ReadTimeout: 
Pattern not detected: 'Info:\\ The\\ configuration\\ takes\\ effect\\ on\\ the\\ current\\ user\\ terminal\\ interface\\ only\\.' in output.

Things you might try to fix this:
1. Explicitly set your pattern using the expect_string argument.
2. Increase the read_timeout to a larger value.

You can also look at the Netmiko session_log or debug log for more information.



2022-12-06 19:56:32,230 -  nornir.core -     INFO -        run() - Running task 'netmiko_send_command' with args {'command_string': 'disp ip int bri', 'use_genie': True} on 2 hosts
2022-12-06 19:56:43,746 - nornir.core.task -    ERROR -      start() - Host 'CE1': task 'netmiko_send_command' failed with traceback:
Traceback (most recent call last):
  File "/root/venv3/lib64/python3.9/site-packages/nornir/core/task.py", line 99, in start
    r = self.task(self, **self.params)
  File "/root/venv3/lib64/python3.9/site-packages/nornir_netmiko/tasks/netmiko_send_command.py", line 32, in netmiko_send_command
    result = net_connect.send_command(command_string, **kwargs)
  File "/root/venv3/lib64/python3.9/site-packages/netmiko/utilities.py", line 592, in wrapper_decorator
    return func(self, *args, **kwargs)
  File "/root/venv3/lib64/python3.9/site-packages/netmiko/base_connection.py", line 1721, in send_command
    raise ReadTimeout(msg)
netmiko.exceptions.ReadTimeout: 
Pattern not detected: 'Info:\\ The\\ configuration\\ takes\\ effect\\ on\\ the\\ current\\ user\\ terminal\\ interface\\ only\\.' in output.

Things you might try to fix this:
1. Explicitly set your pattern using the expect_string argument.
2. Increase the read_timeout to a larger value.

You can also look at the Netmiko session_log or debug log for more information.



2022-12-06 19:59:12,991 -  nornir.core -     INFO -        run() - Running task 'netmiko_send_command' with args {'command_string': 'disp ip int bri', 'use_textfsm': True} on 2 hosts
2022-12-06 20:01:42,746 -  nornir.core -  WARNING -        run() - Task 'netmiko_send_command' has not been run – 0 hosts selected
2022-12-06 20:02:02,887 -  nornir.core -  WARNING -        run() - Task 'netmiko_send_command' has not been run – 0 hosts selected
2022-12-06 20:04:48,494 -  nornir.core -     INFO -        run() - Running task 'netmiko_send_command' with args {'command_string': 'disp ip int bri', 'use_textfsm': True} on 1 hosts
2022-12-06 22:09:39,223 -  nornir.core -     INFO -        run() - Running task 'netmiko_send_command' with args {'command_string': 'disp bgp vpnv4 vpn-inst ABC rou', 'use_textfsm': True} on 1 hosts
2022-12-06 22:11:52,411 -  nornir.core -     INFO -        run() - Running task 'netmiko_send_command' with args {'command_string': 'disp bgp vpnv4 vpn-inst ABC rou', 'use_textfsm': True} on 1 hosts
2022-12-06 22:12:42,569 -  nornir.core -     INFO -        run() - Running task 'netmiko_send_command' with args {'command_string': 'disp bgp vpnv4 vpn-inst ABC rou'} on 1 hosts
2022-12-08 10:47:12,678 -  nornir.core -     INFO -        run() - Running task 'netmiko_send_command' with args {'command_string': 'disp bgp vpnv4 all routi 6.6.6.6', 'use_textfsm': True} on 1 hosts
2022-12-08 10:55:00,469 -  nornir.core -     INFO -        run() - Running task 'netmiko_send_command' with args {'command_string': 'disp bgp vpnv4 all routi 6.6.6.6', 'use_textfsm': True} on 1 hosts
2022-12-08 10:59:50,724 -  nornir.core -     INFO -        run() - Running task 'netmiko_send_command' with args {'command_string': 'disp bgp vpnv4 all routi 6.6.6.6', 'use_textfsm': True} on 1 hosts
2022-12-08 11:06:27,706 -  nornir.core -     INFO -        run() - Running task 'netmiko_send_command' with args {'command_string': 'dis bgp vpnv4 all routing-table 6.6.6.6', 'use_textfsm': True} on 1 hosts
2022-12-08 11:22:43,078 -  nornir.core -     INFO -        run() - Running task 'netmiko_send_command' with args {'command_string': 'display interface brief', 'use_textfsm': True} on 1 hosts
2022-12-08 11:28:04,716 -  nornir.core -     INFO -        run() - Running task 'netmiko_send_command' with args {'command_string': 'sh interfaces switchport', 'use_textfsm': True} on 6 hosts
2022-12-08 11:28:34,978 -  nornir.core -     INFO -        run() - Running task 'netmiko_send_command' with args {'command_string': 'sh interfaces switchport'} on 6 hosts
2022-12-08 15:02:37,593 -  nornir.core -     INFO -        run() - Running task 'netmiko_send_command' with args {'command_string': 'sh int switchport'} on 6 hosts
2022-12-08 15:02:46,824 -  nornir.core -     INFO -        run() - Running task 'netmiko_send_command' with args {'command_string': 'sh interfaces switchport', 'use_textfsm': True} on 6 hosts
2022-12-09 16:02:16,543 -  nornir.core -     INFO -        run() - Running task 'napalm_get' with args {'getters': ['facts', 'interfaces_ip']} on 6 hosts
2022-12-09 16:02:16,570 - nornir.core.task -    ERROR -      start() - Host 'PE1': task 'napalm_get' failed with traceback:
Traceback (most recent call last):
  File "/root/venv3/lib64/python3.9/site-packages/nornir/core/task.py", line 99, in start
    r = self.task(self, **self.params)
  File "/root/venv3/lib64/python3.9/site-packages/nornir_napalm/plugins/tasks/napalm_get.py", line 32, in napalm_get
    device = task.host.get_connection(CONNECTION_NAME, task.nornir.config)
  File "/root/venv3/lib64/python3.9/site-packages/nornir/core/inventory.py", line 494, in get_connection
    self.open_connection(
  File "/root/venv3/lib64/python3.9/site-packages/nornir/core/inventory.py", line 546, in open_connection
    conn_obj.open(
  File "/root/venv3/lib64/python3.9/site-packages/nornir_napalm/plugins/connections/__init__.py", line 55, in open
    network_driver = get_network_driver(platform)
  File "/root/venv3/lib64/python3.9/site-packages/napalm/base/__init__.py", line 99, in get_network_driver
    raise ModuleImportError(
napalm.base.exceptions.ModuleImportError: Cannot import "huawei". Is the library installed?

2022-12-09 16:02:16,572 - nornir.core.task -    ERROR -      start() - Host 'CE1': task 'napalm_get' failed with traceback:
Traceback (most recent call last):
  File "/root/venv3/lib64/python3.9/site-packages/nornir/core/task.py", line 99, in start
    r = self.task(self, **self.params)
  File "/root/venv3/lib64/python3.9/site-packages/nornir_napalm/plugins/tasks/napalm_get.py", line 32, in napalm_get
    device = task.host.get_connection(CONNECTION_NAME, task.nornir.config)
  File "/root/venv3/lib64/python3.9/site-packages/nornir/core/inventory.py", line 494, in get_connection
    self.open_connection(
  File "/root/venv3/lib64/python3.9/site-packages/nornir/core/inventory.py", line 546, in open_connection
    conn_obj.open(
  File "/root/venv3/lib64/python3.9/site-packages/nornir_napalm/plugins/connections/__init__.py", line 55, in open
    network_driver = get_network_driver(platform)
  File "/root/venv3/lib64/python3.9/site-packages/napalm/base/__init__.py", line 99, in get_network_driver
    raise ModuleImportError(
napalm.base.exceptions.ModuleImportError: Cannot import "huawei". Is the library installed?

2022-12-09 16:56:07,520 -  nornir.core -     INFO -        run() - Running task 'napalm_get' with args {'getters': ['facts', 'interfaces_ip']} on 6 hosts
2022-12-09 16:56:07,558 - nornir.core.task -    ERROR -      start() - Host 'CE1': task 'napalm_get' failed with traceback:
Traceback (most recent call last):
  File "/root/venv3/lib64/python3.9/site-packages/nornir/core/task.py", line 99, in start
    r = self.task(self, **self.params)
  File "/root/venv3/lib64/python3.9/site-packages/nornir_napalm/plugins/tasks/napalm_get.py", line 32, in napalm_get
    device = task.host.get_connection(CONNECTION_NAME, task.nornir.config)
  File "/root/venv3/lib64/python3.9/site-packages/nornir/core/inventory.py", line 494, in get_connection
    self.open_connection(
  File "/root/venv3/lib64/python3.9/site-packages/nornir/core/inventory.py", line 546, in open_connection
    conn_obj.open(
  File "/root/venv3/lib64/python3.9/site-packages/nornir_napalm/plugins/connections/__init__.py", line 55, in open
    network_driver = get_network_driver(platform)
  File "/root/venv3/lib64/python3.9/site-packages/napalm/base/__init__.py", line 99, in get_network_driver
    raise ModuleImportError(
napalm.base.exceptions.ModuleImportError: Cannot import "huawei". Is the library installed?

2022-12-09 16:56:07,559 - nornir.core.task -    ERROR -      start() - Host 'PE1': task 'napalm_get' failed with traceback:
Traceback (most recent call last):
  File "/root/venv3/lib64/python3.9/site-packages/nornir/core/task.py", line 99, in start
    r = self.task(self, **self.params)
  File "/root/venv3/lib64/python3.9/site-packages/nornir_napalm/plugins/tasks/napalm_get.py", line 32, in napalm_get
    device = task.host.get_connection(CONNECTION_NAME, task.nornir.config)
  File "/root/venv3/lib64/python3.9/site-packages/nornir/core/inventory.py", line 494, in get_connection
    self.open_connection(
  File "/root/venv3/lib64/python3.9/site-packages/nornir/core/inventory.py", line 546, in open_connection
    conn_obj.open(
  File "/root/venv3/lib64/python3.9/site-packages/nornir_napalm/plugins/connections/__init__.py", line 55, in open
    network_driver = get_network_driver(platform)
  File "/root/venv3/lib64/python3.9/site-packages/napalm/base/__init__.py", line 99, in get_network_driver
    raise ModuleImportError(
napalm.base.exceptions.ModuleImportError: Cannot import "huawei". Is the library installed?

2022-12-09 17:05:36,292 -  nornir.core -     INFO -        run() - Running task 'netmiko_send_command' with args {'command_string': 'sh int switchport'} on 6 hosts
2022-12-09 17:08:07,863 -  nornir.core -     INFO -        run() - Running task 'netmiko_send_command' with args {'command_string': 'disp ip int brief'} on 2 hosts
2022-12-09 17:10:45,129 -  nornir.core -     INFO -        run() - Running task "Backing up SW's configuration" with args {} on 2 hosts
2022-12-09 17:10:45,140 - nornir.core.task -    ERROR -      start() - Host 'PE1': task 'napalm_get' failed with traceback:
Traceback (most recent call last):
  File "/root/venv3/lib64/python3.9/site-packages/nornir/core/task.py", line 99, in start
    r = self.task(self, **self.params)
  File "/root/venv3/lib64/python3.9/site-packages/nornir_napalm/plugins/tasks/napalm_get.py", line 32, in napalm_get
    device = task.host.get_connection(CONNECTION_NAME, task.nornir.config)
  File "/root/venv3/lib64/python3.9/site-packages/nornir/core/inventory.py", line 494, in get_connection
    self.open_connection(
  File "/root/venv3/lib64/python3.9/site-packages/nornir/core/inventory.py", line 546, in open_connection
    conn_obj.open(
  File "/root/venv3/lib64/python3.9/site-packages/nornir_napalm/plugins/connections/__init__.py", line 55, in open
    network_driver = get_network_driver(platform)
  File "/root/venv3/lib64/python3.9/site-packages/napalm/base/__init__.py", line 99, in get_network_driver
    raise ModuleImportError(
napalm.base.exceptions.ModuleImportError: Cannot import "huawei". Is the library installed?

2022-12-09 17:10:45,141 - nornir.core.task -    ERROR -      start() - Host 'CE1': task 'napalm_get' failed with traceback:
Traceback (most recent call last):
  File "/root/venv3/lib64/python3.9/site-packages/nornir/core/task.py", line 99, in start
    r = self.task(self, **self.params)
  File "/root/venv3/lib64/python3.9/site-packages/nornir_napalm/plugins/tasks/napalm_get.py", line 32, in napalm_get
    device = task.host.get_connection(CONNECTION_NAME, task.nornir.config)
  File "/root/venv3/lib64/python3.9/site-packages/nornir/core/inventory.py", line 494, in get_connection
    self.open_connection(
  File "/root/venv3/lib64/python3.9/site-packages/nornir/core/inventory.py", line 546, in open_connection
    conn_obj.open(
  File "/root/venv3/lib64/python3.9/site-packages/nornir_napalm/plugins/connections/__init__.py", line 55, in open
    network_driver = get_network_driver(platform)
  File "/root/venv3/lib64/python3.9/site-packages/napalm/base/__init__.py", line 99, in get_network_driver
    raise ModuleImportError(
napalm.base.exceptions.ModuleImportError: Cannot import "huawei". Is the library installed?

2022-12-09 17:10:45,142 - nornir.core.task -    ERROR -      start() - Host 'PE1': task "Backing up SW's configuration" failed with traceback:
Traceback (most recent call last):
  File "/root/venv3/lib64/python3.9/site-packages/nornir/core/task.py", line 99, in start
    r = self.task(self, **self.params)
  File "/root/py/py_test/nornir7.py", line 12, in backup_configurations
    r=cisco.run(task=napalm_get, getters=["config"])
  File "/root/venv3/lib64/python3.9/site-packages/nornir/core/task.py", line 174, in run
    raise NornirSubTaskError(task=run_task, result=r)
nornir.core.exceptions.NornirSubTaskError: Subtask: napalm_get (failed)


2022-12-09 17:10:45,143 - nornir.core.task -    ERROR -      start() - Host 'CE1': task "Backing up SW's configuration" failed with traceback:
Traceback (most recent call last):
  File "/root/venv3/lib64/python3.9/site-packages/nornir/core/task.py", line 99, in start
    r = self.task(self, **self.params)
  File "/root/py/py_test/nornir7.py", line 12, in backup_configurations
    r=cisco.run(task=napalm_get, getters=["config"])
  File "/root/venv3/lib64/python3.9/site-packages/nornir/core/task.py", line 174, in run
    raise NornirSubTaskError(task=run_task, result=r)
nornir.core.exceptions.NornirSubTaskError: Subtask: napalm_get (failed)


2022-12-09 17:17:21,577 -  nornir.core -     INFO -        run() - Running task 'netmiko_send_command' with args {'command_string': 'sh interfaces switchport', 'use_textfsm': True} on 6 hosts
